<?xml version="1.0"?>
<robot xmlns:xacro="http://www.ros.org/wiki/xacro" name="mobile_base">

    <material name="gray">
        <color rgba="0.5 0.5 0.5 1"/>
    </material>
    <material name="red">
        <color rgba="1 0 0 1"/>
    </material>
    <material name="blue">
        <color rgba="0 0 1 1"/>
    </material>

  <!-- Base Link -->
  <link name="base_link">
    <inertial>
      <origin xyz="-0.1 0 -0.1" rpy="0 0 0"/>
      <mass value="10.0"/>
      <inertia ixx="0.25" ixy="0.0" ixz="0.0" iyy="0.5" iyz="0.0" izz="0.05"/>
    </inertial>
    <visual>
      <origin xyz="0 0 0" rpy="0 0 0"/>
      <geometry>
        <box size="0.5 0.5 0.3"/>
      </geometry>
      <material name="gray"/>
    </visual>
    <collision>
      <origin xyz="0 0 0" rpy="0 0 0"/>
      <geometry>
        <box size="0.5 0.5 0.3"/>
      </geometry>
    </collision>
  </link>

  <!-- Laser Link -->
  <link name="laser_link">
    <visual>
      <origin xyz="0.01 0 0.2" rpy="0 0 0"/>
      <geometry>
        <cylinder length="0.05" radius="0.03"/>
      </geometry>
      <material name="red"/>
    </visual>
  </link>

  <!-- Joints -->
  <joint name="laser_joint" type="fixed">
    <parent link="base_link"/>
    <child link="laser_link"/>
    <origin xyz="0.01 0 0.2" rpy="0 0 0"/>
  </joint>

  <!-- Left Wheel -->
  <link name="left_wheel">
  <visual>
    <origin xyz="0 0 0" rpy="0 0 0"/>
    <geometry>
      <cylinder radius="0.125" length="0.05"/>
    </geometry>
    <material name="gray"/>
  </visual>
  <collision>
    <origin xyz="0 0 0" rpy="0 0 0"/>
    <geometry>
      <cylinder radius="0.125" length="0.05"/>
    </geometry>
  </collision>
</link>
  <joint name="left_wheel_hinge" type="continuous">
    <parent link="base_link"/>
    <child link="left_wheel"/>
    <origin xyz="0.2 0.29 0.125" rpy="0 1.5707 1.5707"/>
    <axis xyz="0 1 0"/>
  </joint>

  <!-- Right Wheel -->
    <link name="right_wheel">
        <visual>
            <origin xyz="0 0 0" rpy="0 0 0"/>
            <geometry>
                <cylinder radius="0.125" length="0.05"/>
            </geometry>
            <material name="gray"/>
        </visual>
        <collision>
            <origin xyz="0 0 0" rpy="0 0 0"/>
            <geometry>
                <cylinder radius="0.125" length="0.05"/>
            </geometry>
        </collision>
    </link>
  <joint name="right_wheel_hinge" type="continuous">
    <parent link="base_link"/>
    <child link="right_wheel"/>
    <origin xyz="0.2 -0.29 0.125" rpy="0 1.5707 1.5707"/>
    <axis xyz="0 1 0"/>
  </joint>

  <!-- Caster Wheel -->
    <link name="caster_wheel">
    <visual>
        <origin xyz="0 0 0" rpy="0 0 0"/>
        <geometry>
        <sphere radius="0.125"/>
        </geometry>
        <material name="blue"/>
    </visual>
    <collision>
        <origin xyz="0 0 0" rpy="0 0 0"/>
        <geometry>
        <sphere radius="0.125"/>
        </geometry>
    </collision>
    </link>

    <joint name="caster_joint" type="fixed">
    <parent link="base_link"/>
    <child link="caster_wheel"/>
    <origin xyz="-0.2 0 -0.125" rpy="0 0 0"/>
    </joint>


</robot>
