<?xml version='1.0'?>
<sdf version='1.5'>
  <model name="mobile_base">
    <link name='chassis'>
      <pose>0 0 .25 0 0 0</pose>

      <inertial>
        <mass>10.0</mass>
        <pose>-0.1 0 -0.1 0 0 0</pose>
        <inertia>
          <ixx>0.25</ixx>
          <iyy>0.5</iyy>
          <izz>0.05</izz>
        </inertia>
      </inertial>

      <collision name='collision'>
        <geometry>
          <box>
            <size>0.5 0.5 0.3</size>
          </box>
        </geometry>
      </collision>

      <visual name='visual'>
        <geometry>
          <box>
            <size>0.5 0.5 0.3</size>
          </box>
        </geometry>
      </visual>

      <collision name='caster_collision'>
        <pose>-0.2 0 -0.125 0 0 0</pose>
        <geometry>
          <sphere>
            <radius>.125</radius>
          </sphere>
        </geometry>

        <surface>
          <friction>
            <ode>
              <mu>0</mu>
              <mu2>0</mu2>
            </ode>
          </friction>
        </surface>
      </collision>

      <visual name='caster_visual'>
        <pose>-0.2 0 -0.125 0 0 0</pose>
        <geometry>
          <sphere>
            <radius>.125</radius>
          </sphere>
        </geometry>
      </visual>
      
      <sensor name="laser" type="ray">
		    <pose>0.01 0 0.2 0 -0 0</pose>
		    <ray>
		      <scan>
		        <horizontal>
		          <samples>640</samples>
		          <resolution>1</resolution>
		          <min_angle>-3.14</min_angle>
		          <max_angle>3.14</max_angle>
		        </horizontal>
		      </scan>
		      <range>
		        <min>0.08</min>
		        <max>10</max>
		        <resolution>0.01</resolution>
		      </range>
		      <noise>
		        <type>gaussian</type>
		        <mean>0.0</mean>
		        <stddev>0.01</stddev>
		      </noise>
		    </ray>
		    <plugin name="laser" filename="libRayPlugin.so" />
		    <always_on>1</always_on>
		    <update_rate>30</update_rate>
		    <visualize>true</visualize>
		  </sensor>
    </link>
    
    
    <link name="left_wheel">
      <pose>0.2 0.29 0.125 0 1.5707 1.5707</pose>
      <collision name="collision">
        <geometry>
          <cylinder>
            <radius>.125</radius>
            <length>.05</length>
          </cylinder>
        </geometry>
      </collision>
      <visual name="visual">
        <geometry>
          <cylinder>
            <radius>.125</radius>
            <length>.05</length>
          </cylinder>
        </geometry>
      </visual>
    </link>

    <link name="right_wheel">
      <pose>0.2 -0.29 0.125 0 1.5707 1.5707</pose>
      <collision name="collision">
        <geometry>
          <cylinder>
            <radius>.125</radius>
            <length>.05</length>
          </cylinder>
        </geometry>
      </collision>
      <visual name="visual">
        <geometry>
          <cylinder>
            <radius>.125</radius>
            <length>.05</length>
          </cylinder>
        </geometry>
      </visual>
    </link>

    <joint type="revolute" name="left_wheel_hinge">
      <pose>0 0 -0.03 0 0 0</pose>
      <child>left_wheel</child>
      <parent>chassis</parent>
      <axis>
        <use_parent_model_frame>true</use_parent_model_frame>
        <xyz>0 1 0</xyz>
      </axis>
    </joint>

    <joint type="revolute" name="right_wheel_hinge">
      <pose>0 0 0.03 0 0 0</pose>
      <child>right_wheel</child>
      <parent>chassis</parent>
      <axis>
        <use_parent_model_frame>true</use_parent_model_frame>
        <xyz>0 1 0</xyz>
      </axis>
    </joint>

  </model>
 </sdf>
